Workbook

Sheet Summary
A1: SpeakSharp — updated financial model
A2: Forecast version 2026-10-12 · Unvalidated planning case: current private STT, $10/month after 30-day trial · $7 and $5 alternatives on Price Sensitivity
J3: Period | K3: Historical | L3: Current organic | M3: Current paid CAC
A4: Planning conclusion: under the stated assumptions, the lean stack lowers fixed cost. Trial conversion, lifetime, usage, CAC and revenue remain unmeasured hypotheses; use this workbook for sensitivity planning, not release or investment proof. | J4: =TEXT('Forecast 12M'!B$4,"mmm yy") -> Sep 26 | K4: ='Forecast 12M'!B$12 -> 0.8 | L4: ='Forecast 12M'!B$27 -> -58.125 | M4: ='Forecast 12M'!B$42 -> -243.875
J5: =TEXT('Forecast 12M'!C$4,"mmm yy") -> Oct 26 | K5: ='Forecast 12M'!C$12 -> 96.4 | L5: ='Forecast 12M'!C$27 -> -23.1125 | M5: ='Forecast 12M'!C$42 -> -394.6125
J6: =TEXT('Forecast 12M'!D$4,"mmm yy") -> Nov 26 | K6: ='Forecast 12M'!D$12 -> 286.8 | L6: ='Forecast 12M'!D$27 -> 105.0375 | M6: ='Forecast 12M'!D$42 -> -452.2125
J7: =TEXT('Forecast 12M'!E$4,"mmm yy") -> Dec 26 | K7: ='Forecast 12M'!E$12 -> 572 | L7: ='Forecast 12M'!E$27 -> 326.325 | M7: ='Forecast 12M'!E$42 -> -416.675
A8: Lean fixed OpEx | C8: Contribution / paid user | E8: Break-even paid users | G8: 3:1 CAC ceiling | J8: =TEXT('Forecast 12M'!F$4,"mmm yy") -> Jan 27 | K8: ='Forecast 12M'!F$12 -> 952 | L8: ='Forecast 12M'!F$27 -> 626.575 | M8: ='Forecast 12M'!F$42 -> -302.175
A9: =Assumptions!B25 -> 45 | C9: ='Unit Economics'!B11 -> 9.2875 | E9: ='Unit Economics'!B13 -> 5 | G9: ='Unit Economics'!B16 -> 18.575 | J9: =TEXT('Forecast 12M'!G$4,"mmm yy") -> Feb 27 | K9: ='Forecast 12M'!G$12 -> 1426.8 | L9: ='Forecast 12M'!G$27 -> 1019.7 | M9: ='Forecast 12M'!G$42 -> -94.8
J10: =TEXT('Forecast 12M'!H$4,"mmm yy") -> Mar 27 | K10: ='Forecast 12M'!H$12 -> 1901.6 | L10: ='Forecast 12M'!H$27 -> 1505.7 | M10: ='Forecast 12M'!H$42 -> 205.45
J11: =TEXT('Forecast 12M'!I$4,"mmm yy") -> Apr 27 | K11: ='Forecast 12M'!I$12 -> 2376.4 | L11: ='Forecast 12M'!I$27 -> 1991.7 | M11: ='Forecast 12M'!I$42 -> 505.7
J12: =TEXT('Forecast 12M'!J$4,"mmm yy") -> May 27 | K12: ='Forecast 12M'!J$12 -> 2851.2 | L12: ='Forecast 12M'!J$27 -> 2477.7 | M12: ='Forecast 12M'!J$42 -> 805.95
A13: Old versus current — what changed | J13: =TEXT('Forecast 12M'!K$4,"mmm yy") -> Jun 27 | K13: ='Forecast 12M'!K$12 -> 3326 | L13: ='Forecast 12M'!K$27 -> 2963.7 | M13: ='Forecast 12M'!K$42 -> 1106.2
A14: Metric | B14: Feb 23 model | C14: Current lean | D14: Current monitored | E14: Delta vs Feb 23 | F14: Still holds? | G14: Why | H14: Management action | J14: =TEXT('Forecast 12M'!L$4,"mmm yy") -> Jul 27 | K14: ='Forecast 12M'!L$12 -> 3800.8 | L14: ='Forecast 12M'!L$27 -> 3449.7 | M14: ='Forecast 12M'!L$42 -> 1406.45
A15: Monthly price | B15: 14.99 | C15: =Assumptions!B13 -> 10 | D15: =Assumptions!B13 -> 10 | E15: =C15-B15 -> -4.99 | F15: Changed | G15: Current posture is $10 after trial | H15: Validate willingness to pay after product truth fixes | J15: =TEXT('Forecast 12M'!M$4,"mmm yy") -> Aug 27 | K15: ='Forecast 12M'!M$12 -> 4275.6 | L15: ='Forecast 12M'!M$27 -> 3935.7 | M15: ='Forecast 12M'!M$42 -> 1706.7
A16: Fixed software OpEx | B16: 94 | C16: =Assumptions!B25 -> 45 | D16: =Assumptions!B26 -> 71 | E16: =C16-B16 -> -49 | F16: Improved | G16: Lean stack is materially smaller | H16: Hold lean until monitoring volume requires Team
A17: Variable cost / paid user | B17: 5.51 | C17: =Assumptions!B13-'Unit Economics'!B11 -> 0.7125 | D17: =Assumptions!B13-'Unit Economics'!B11 -> 0.7125 | E17: =C17-B17 -> -4.7975 | F17: Improved | G17: AssemblyAI removed; private STT is on-device | H17: Watch model egress, not cloud STT hours
A18: Contribution / paid user | B18: 9.48 | C18: ='Unit Economics'!B11 -> 9.2875 | D18: ='Unit Economics'!B11 -> 9.2875 | E18: =C18-B18 -> -0.1925 | F18: Mostly holds | G18: Lower price offset by lower variable cost | H18: Use $9.29 for planning
A19: 6-month contribution LTV | B19: 56.88 | C19: ='Unit Economics'!B15 -> 55.725 | D19: ='Unit Economics'!B15 -> 55.725 | E19: =C19-B19 -> -1.155 | F19: Corrected | G19: Prior $85 claim did not tie | H19: Use formula-based LTV only
A20: 3:1 CAC ceiling | B20: 18.96 | C20: ='Unit Economics'!B16 -> 18.575 | D20: ='Unit Economics'!B16 -> 18.575 | E20: =C20-B20 -> -0.385 | F20: Mostly holds | G20: Corrected LTV implies about $19, not $28 | H20: Do not buy growth above model ceiling
A21: Break-even active paid users | B21: 10 | C21: ='Unit Economics'!B13 -> 5 | D21: ='Unit Economics'!B14 -> 8 | E21: =C21-B21 -> -5 | F21: Improved | G21: Lower fixed OpEx | H21: Lean target is five active paid users
A24: Profitability timing under the preserved ramp
A25: Scenario | B25: First monthly profit | C25: Cumulative cash ≥ $0 | D25: What is included | F25: Targets to chase • 500 new trials per month • ≥2% trial-to-paid conversion • ≥6-month paid lifetime • CAC ≤ $18.58 • Lean stack until monitoring justifies the upgrade
A26: Historical Feb 23 | B26: Month 1 | C26: Month 1 | D26: No trial delay; no acquisition spend
A27: Current organic | B27: ="Month "&MATCH("Yes",'Forecast 12M'!B28:M28,0) -> Month 2 | C27: ="Month "&MATCH("Yes",'Forecast 12M'!B29:M29,0) -> Month 3 | D27: 30-day trial; trial + paid coaching cost; lean stack; no paid CAC
A28: Current paid acquisition | B28: ="Month "&MATCH("Yes",'Forecast 12M'!B43:M43,0) -> Month 4 | C28: ="Month "&MATCH("Yes",'Forecast 12M'!B44:M44,0) -> Month 7 | D28: 30-day trial; trial + paid coaching cost; lean stack; spend at 3:1 CAC ceiling
A32: Forecast scope: subscription revenue, Stripe fees, Gemini usage, software subscriptions and modeled customer acquisition. Excluded: taxes, refunds/chargebacks, payroll/founder compensation, legal/accounting, domain costs, one-time launch work, and usage overages beyond vendor allowances. Billing is not live today, so all revenue is projected.

Sheet Assumptions
A1: SpeakSharp financial model — assumptions
A2: Yellow cells are editable assumptions. Blue cells are formulas. Forecast, not a promise; taxes, founder compensation and one-time legal/accounting costs are excluded.
A4: Current operating model
A5: Driver | B5: Value | C5: Units | D5: Type | E5: Source / rationale | F5: Owner note
A6: Forecast start | B6: 46266 | C6: month | D6: Input | E6: Current planning date | F6: Change to refresh timeline
A7: Forecast horizon | B7: =COLUMNS('Forecast 12M'!B3:M3) -> 12 | C7: months | D7: Formula | E7: Count of forecast month columns | F7: Fixed layout; extend Forecast 12M and this formula together
A8: Trial-to-paid conversion | B8: 0.02 | C8: % | D8: Input | E8: Preserved from prior models | F8: Target to validate
A9: New trial users / month | B9: 500 | C9: users | D9: Input | E9: Implies 10 new paid/month at 2% | F9: Same ramp as prior
A10: New paid users / month | B10: =B8*B9 -> 10 | C10: users | D10: Formula | E10: Conversion × new trials | F10: Derived
A11: Paid lifetime | B11: 6 | C11: months | D11: Input | E11: Preserved from prior models | F11: Cohort expires after month 6
A12: Free trial delay | B12: 1 | C12: months | D12: Input | E12: Current product: 30-day complete trial | F12: Creates one-month cash delay
A13: Monthly price | B13: 10 | C13: USD / paid user | D13: Input | E13: Current product posture | F13: Billing not yet activated
A14: AI generations / active trial or paid user / month | B14: 10 | C14: calls | D14: Input | E14: Editable usage assumption | F14: Editable planning assumption; trial and paid capabilities are equal
A15: Input tokens / AI call | B15: 2500 | C15: tokens | D15: Input | E15: Approx. 8,000-char transcript plus prompt | F15: Editable
A16: Output tokens / AI call | B16: 200 | C16: tokens | D16: Input | E16: Two concise phrases in each coaching section | F16: Excludes Gemini thinking tokens (unmeasured; see B33)
A17: Stripe Payments rate | B17: 0.029 | C17: % of charge | D17: Source | E17: Stripe standard domestic card price | F17: Excludes international/add-ons
A18: Stripe fixed fee | B18: 0.3 | C18: USD / charge | D18: Source | E18: Stripe standard domestic card price | F18: One monthly charge
A19: Stripe Billing rate | B19: 0.007 | C19: % of billing volume | D19: Source | E19: Stripe Billing pay-as-you-go
A20: Gemini 3.8 Flash input — through 2026 | B20: 0.75 | C20: USD / 1M tokens | D20: Source | E20: Current code model gemini-3.8-flash (#1586); same published price as 3.6 Flash
A21: Gemini 3.8 Flash output — through 2026 | B21: 3.75 | C21: USD / 1M tokens | D21: Source | E21: Official pricing; output price includes thinking tokens
A22: Gemini 3.8 Flash input — 2027 onward | B22: 1.5 | C22: USD / 1M tokens | D22: Source | E22: Published 2027 price (from 2027-01-01)
A23: Gemini 3.8 Flash output — 2027 onward | B23: 7.5 | C23: USD / 1M tokens | D23: Source | E23: Published 2027 price; includes thinking tokens
A24: Gemini price step date | B24: 46388 | C24: date | D24: Source | E24: Official pricing schedule
A25: Lean fixed software stack | B25: =SUM('Stack Comparison'!C7:C17) -> 45 | C25: USD / month | D25: Formula | E25: Supabase Pro $25 + Vercel Pro $20 | F25: Gmail, PostHog, Sentry Developer, GitHub = $0 incremental
A26: Monitored fixed software stack | B26: =SUM('Stack Comparison'!D7:D17) -> 71 | C26: USD / month | D26: Formula | E26: Lean + Sentry Team $26 | F26: Optional operating posture
A27: Selected fixed-cost posture | B27: Lean | C27: Lean / Monitored | D27: Input | E27: Base case | F27: Use dropdown
A28: Selected fixed OpEx | B28: =IF(B27="Monitored",B26,B25) -> 45 | C28: USD / month | D28: Formula | E28: Selected posture | F28: Derived
A29: Paid-acquisition scenario | B29: 3:1 CAC ceiling | C29: scenario | D29: Input | E29: Marketing target scenario | F29: Organic scenario remains separate
A30: CAC ceiling | B30: =(B13-(B13*B17+B18+B13*B19)-B14*(B15/1000000*B22+B16/1000000*B23))*B11/3 -> 18.575 | C30: USD / new paid user | D30: Formula | E30: Six-month contribution LTV ÷ 3 | F30: Conservative 2027 Gemini price
A31: Starting cash | B31: 0 | C31: USD | D31: Input | E31: Incremental model starts at zero | F31: Add cash balance if using as runway model
A32: Uncached coaching cap / user / UTC day | B32: 10 | C32: calls | D32: Source | E32: contract.json uncachedGenerationCapPerUtcDay | F32: Bounds heavy-user exposure
A33: Thinking tokens / AI call (sensitivity) | B33: 1000 | C33: tokens | D33: Input | E33: Unmeasured: thinking_level unset (default medium); token usage not logged | F33: Illustrative; replace with measured thoughtsTokenCount
A34: Historical assumptions preserved for like-for-like comparison
A35: Driver | B35: Feb 1 original | C35: Feb 23 revised | D35: Archive lean | E35: Current | F35: Notes
A36: Monthly price | B36: 7.99 | C36: 14.99 | D36: 7.99 | E36: =Assumptions!B13 -> 10 | F36: Current price is $10 after trial
A37: Conversion | B37: 0.02 | C37: 0.02 | D37: 0.02 | E37: =Assumptions!B8 -> 0.02 | F37: Held constant
A38: New paid users / month | B38: 10 | C38: 10 | D38: 10 | E38: =Assumptions!B10 -> 10 | F38: Current begins after one-month trial
A39: Paid lifetime (months) | B39: 6 | C39: 6 | D39: 6 | E39: =Assumptions!B11 -> 6 | F39: Held constant
A40: Fixed software OpEx | B40: 25 | C40: 94 | D40: 45 | E40: =Assumptions!B25 -> 45 | F40: Lean current posture
A41: Contribution / paid user | B41: 7.1 | C41: 9.48 | D41: 5.54 | E41: ='Unit Economics'!B11 -> 9.2875 | F41: Revenue less variable cost

Sheet Stack Comparison
A1: Software stack — historical versus current
A2: Like-for-like monthly costs; official prices re-checked 2026-10-12 with no list-price change since 2026-09-05. Historical Resend remains shown; current/project email uses existing Gmail at $0 incremental. Google Workspace is an optional $7/month alternative, not in the base case.
A4: Current base posture: private/on-device STT; no AssemblyAI and no browser-native STT. Gemini is used only for user-requested coaching. Vendor usage overages are excluded until actual volumes exceed included allowances. | I4: Posture | J4: Historical | K4: Current lean | L4: Current monitored
I5: Fixed monthly OpEx | J5: 94 | K5: 45 | L5: 71
A6: Service / function | B6: Historical Feb 23 | C6: Current lean | D6: Current monitored | E6: Billing basis | F6: Current posture | G6: Official source | I6: Savings vs historical | J6: 0 | K6: 49 | L6: 23
A7: Supabase | B7: 25 | C7: 25 | D7: 25 | E7: Monthly | F7: Pro; one Micro project covered by compute credit | G7: https://supabase.com/pricing | I7: Optional Gmail Workspace | J7: 0 | K7: 7 | L7: 7
A8: Vercel | B8: 20 | C8: 20 | D8: 20 | E8: Monthly | F8: Pro $20 platform fee incl. $20 usage credit; Flat Rate CDN 1M requests / 1 TB | G8: https://vercel.com/pricing | I8: Total with Workspace | J8: 94 | K8: 52 | L8: 78
A9: Sentry | B9: 29 | C9: 0 | D9: 26 | E9: Monthly | F9: Developer in lean; Team $26/mo billed annually | G9: https://sentry.io/pricing/
A10: Email | B10: 20 | C10: 0 | D10: 0 | E10: Monthly | F10: Historical Resend; current existing Gmail | G10: https://resend.com/pricing
A11: PostHog | B11: 0 | C11: 0 | D11: 0 | E11: Usage | F11: Free tier until limits are exceeded | G11: https://posthog.com/pricing
A12: GitHub / Actions | B12: 0 | C12: 0 | D12: 0 | E12: Usage | F12: Public repository; standard public Actions minutes | G12: https://github.com/pricing
A13: AssemblyAI | B13: 0 | C13: 0 | D13: 0 | E13: Usage | F13: Not in current customer path | G13: https://www.assemblyai.com/pricing
A14: Browser-native STT | B14: 0 | C14: 0 | D14: 0 | E14: Usage | F14: Not used | G14: n/a
A15: Private STT model | B15: 0 | C15: 0 | D15: 0 | E15: Included hosting | F15: ~80.55 MB model served by current hosting | G15: Local bundle: frontend/public/models/whisper-base.en
A16: Gemini coaching | B16: 0 | C16: 0 | D16: 0 | E16: Usage | F16: Per token (gemini-3.8-flash); modeled in variable costs | G16: https://ai.google.dev/gemini-api/docs/pricing
A17: Stripe | B17: 0 | C17: 0 | D17: 0 | E17: Usage | F17: Per successful monthly charge | G17: https://stripe.com/us/pricing
A18: Fixed monthly total | B18: =SUM(B7:B17) -> 94 | C18: =SUM(C7:C17) -> 45 | D18: =SUM(D7:D17) -> 71
A21: Variable-cost comparison per paid user / month
A22: Variable item | B22: Historical Feb 23 | C22: Current 2026 | D22: Current 2027 | E22: Assumption | F22: Impact | G22: Source
A23: Cloud STT | B23: 4.7 | C23: 0 | D23: 0 | E23: Old: 10 hr × $0.47; current private STT | F23: Removed | G23: https://www.assemblyai.com/pricing
A24: Stripe Payments + Billing | B24: ='Prior Models'!C10-B23 -> 0.81 | C24: ='Unit Economics'!B8 -> 0.66 | D24: ='Unit Economics'!B8 -> 0.66 | E24: One $10 domestic monthly charge | F24: Current unavoidable payment cost | G24: https://stripe.com/us/pricing
A25: Gemini coaching | B25: 0 | C25: ='Unit Economics'!B9 -> 0.02625 | D25: ='Unit Economics'!B10 -> 0.0525 | E25: 10 calls; 2,500 input + 200 output tokens each | F25: Very small at modeled use | G25: https://ai.google.dev/gemini-api/docs/pricing
A26: Total variable cost | B26: =SUM(B23:B25) -> 5.51 | C26: =SUM(C23:C25) -> 0.68625 | D26: =SUM(D23:D25) -> 0.7125 | E26: Sum | F26: Drives contribution

Sheet Gemini Options
A1: Gemini model options and coaching cost
A2: Current code uses gemini-3.8-flash (#1586, merged 2026-10-11), priced the same as Gemini 3.6 Flash. Gemini 3 Flash Preview is the former code model. Gemini 3.5 Flash-Lite is the lower-cost candidate but requires a real coaching-quality benchmark before switching.
A4: Model | B4: Status | C4: Input $/1M | D4: Output $/1M | E4: Cost / call | F4: Cost / paid user / month | G4: Relative fit | H4: Decision | I4: Official source
A5: Gemini 3 Flash Preview | B5: Former code model | C5: 0.5 | D5: 3 | E5: =C5*Assumptions!$B$15/1000000+D5*Assumptions!$B$16/1000000 -> 0.00185 | F5: =E5*Assumptions!$B$14 -> 0.0185 | G5: Replaced in #1586 | H5: Replaced | I5: https://ai.google.dev/gemini-api/docs/pricing
A6: Gemini 3.8 Flash — through 2026 | B6: Current code model | C6: 0.75 | D6: 3.75 | E6: =C6*Assumptions!$B$15/1000000+D6*Assumptions!$B$16/1000000 -> 0.002625 | F6: =E6*Assumptions!$B$14 -> 0.02625 | G6: Same published price as 3.6 Flash | H6: Base forecast | I6: https://ai.google.dev/gemini-api/docs/pricing
A7: Gemini 3.8 Flash — 2027 onward | B7: Current code model | C7: 1.5 | D7: 7.5 | E7: =C7*Assumptions!$B$15/1000000+D7*Assumptions!$B$16/1000000 -> 0.00525 | F7: =E7*Assumptions!$B$14 -> 0.0525 | G7: Same model; published step-up | H7: Base forecast from Jan | I7: https://ai.google.dev/gemini-api/docs/pricing
A8: Gemini 3.5 Flash-Lite | B8: Current low-cost option | C8: 0.3 | D8: 2.5 | E8: =C8*Assumptions!$B$15/1000000+D8*Assumptions!$B$16/1000000 -> 0.00125 | F8: =E8*Assumptions!$B$14 -> 0.0125 | G8: Cheaper; quality must be proven | H8: Benchmark candidate | I8: https://ai.google.dev/gemini-api/docs/models/gemini-3.5-flash-lite
A11: Cost sensitivity by AI calls per paid user / month
A12: Calls / month | B12: Legacy 3 Flash | C12: 3.8 Flash 2026 | D12: 3.8 Flash 2027 | E12: 3.5 Flash-Lite
A13: 5 | B13: =$A13*$E$5 -> 0.00925 | C13: =$A13*$E$6 -> 0.013125 | D13: =$A13*$E$7 -> 0.02625 | E13: =$A13*$E$8 -> 0.00625
A14: 10 | B14: =$A14*$E$5 -> 0.0185 | C14: =$A14*$E$6 -> 0.02625 | D14: =$A14*$E$7 -> 0.0525 | E14: =$A14*$E$8 -> 0.0125
A15: 20 | B15: =$A15*$E$5 -> 0.037 | C15: =$A15*$E$6 -> 0.0525 | D15: =$A15*$E$7 -> 0.105 | E15: =$A15*$E$8 -> 0.025
A16: 40 | B16: =$A16*$E$5 -> 0.074 | C16: =$A16*$E$6 -> 0.105 | D16: =$A16*$E$7 -> 0.21 | E16: =$A16*$E$8 -> 0.05
A19: Recommendation: Gemini 3.8 Flash is now the code model and the planning baseline. At modeled usage the 2027 price is about five cents per paid user per month before thinking tokens. Thinking tokens are billed as output and are not yet measured; see Price Sensitivity for the heavy-user threshold.

Sheet Prior Models
A1: Prior model reconstruction and reconciliation
A2: Historical numbers are preserved as previously stated; recalculated rows expose where a prior conclusion did not tie to its own assumptions.
A4: Metric | B4: Feb 1 original | C4: Feb 23 revised | D4: Archive lean | E4: Current lean | F4: Current monitored | G4: Comparison basis | H4: Conclusion
A5: Monthly price | B5: 7.99 | C5: 14.99 | D5: 7.99 | E5: =Assumptions!B13 -> 10 | F5: =Assumptions!B13 -> 10 | G5: USD / paid user | H5: Current is lower than Feb 23
A6: Conversion | B6: 0.02 | C6: 0.02 | D6: 0.02 | E6: =Assumptions!B8 -> 0.02 | F6: =Assumptions!B8 -> 0.02 | G6: % of new trials | H6: Same assumption
A7: New paid users / month | B7: 10 | C7: 10 | D7: 10 | E7: =Assumptions!B10 -> 10 | F7: =Assumptions!B10 -> 10 | G7: Users | H7: Same ramp; current starts after trial
A8: Paid lifetime | B8: 6 | C8: 6 | D8: 6 | E8: =Assumptions!B11 -> 6 | F8: =Assumptions!B11 -> 6 | G8: Months | H8: Same assumption
A9: Fixed software OpEx | B9: 25 | C9: 94 | D9: 45 | E9: =Assumptions!B25 -> 45 | F9: =Assumptions!B26 -> 71 | G9: USD / month | H9: Current lean is $49 below Feb 23
A10: Variable cost / paid user | B10: 0.89 | C10: 5.51 | D10: 2.45 | E10: =Assumptions!B13-'Unit Economics'!B11 -> 0.7125 | F10: =Assumptions!B13-'Unit Economics'!B11 -> 0.7125 | G10: USD / month | H10: Private STT removes cloud-STT cost
A11: Contribution / paid user | B11: 7.1 | C11: 9.48 | D11: 5.54 | E11: ='Unit Economics'!B11 -> 9.2875 | F11: ='Unit Economics'!B11 -> 9.2875 | G11: USD / month | H11: Current nearly matches Feb 23 at lower price
A12: Reported LTV | B12: 44 | C12: 85 | G12: USD | H12: Historical stated value
A13: Recalculated 6-month LTV | B13: =B11*B8 -> 42.6 | C13: =C11*C8 -> 56.88 | D13: =D11*D8 -> 33.24 | E13: ='Unit Economics'!B15 -> 55.725 | F13: ='Unit Economics'!B15 -> 55.725 | G13: Contribution × 6 | H13: Feb 23 $85 did not reconcile
A14: Reported CAC target | C14: 28 | G14: USD | H14: Based on reported $85 LTV
A15: Recalculated 3:1 CAC ceiling | B15: =B13/3 -> 14.2 | C15: =C13/3 -> 18.96 | D15: =D13/3 -> 11.08 | E15: ='Unit Economics'!B16 -> 18.575 | F15: ='Unit Economics'!B16 -> 18.575 | G15: USD | H15: Use formula-driven value
A16: Reported break-even paid users | C16: 10 | D16: 13 | G16: Users | H16: Archive lean claim was high
A17: Recalculated break-even paid users | B17: =CEILING(B9/B11,1) -> 4 | C17: =CEILING(C9/C11,1) -> 10 | D17: =CEILING(D9/D11,1) -> 9 | E17: ='Unit Economics'!B13 -> 5 | F17: ='Unit Economics'!B14 -> 8 | G17: Users | H17: Fixed OpEx ÷ contribution, rounded up
A20: What still holds: a lean software stack can break even with a small paid base. What changes: the current private-STT architecture removes the largest old variable cost, and the fixed stack is materially lower. What did not hold: the prior $85 LTV and archive claim of 13 break-even users were not consistent with their own inputs. Current pricing introduces a 30-day delay before the first paid cohort, so cash timing—not unit margin—is the early constraint.

Sheet Forecast 12M
A1: 12-month forecast — same growth ramp, current cash timing
A2: 500 new trials/month × 2% conversion = 10 new paid users/month. Each paid cohort remains for six months. Current plans have a one-month trial delay; historical comparison does not.
A3: Month # | B3: 1 | C3: 2 | D3: 3 | E3: 4 | F3: 5 | G3: 6 | H3: 7 | I3: 8 | J3: 9 | K3: 10 | L3: 11 | M3: 12
A4: Period | B4: =EDATE(Assumptions!$B$6,0) -> 46266 | C4: =EDATE(Assumptions!$B$6,1) -> 46296 | D4: =EDATE(Assumptions!$B$6,2) -> 46327 | E4: =EDATE(Assumptions!$B$6,3) -> 46357 | F4: =EDATE(Assumptions!$B$6,4) -> 46388 | G4: =EDATE(Assumptions!$B$6,5) -> 46419 | H4: =EDATE(Assumptions!$B$6,6) -> 46447 | I4: =EDATE(Assumptions!$B$6,7) -> 46478 | J4: =EDATE(Assumptions!$B$6,8) -> 46508 | K4: =EDATE(Assumptions!$B$6,9) -> 46539 | L4: =EDATE(Assumptions!$B$6,10) -> 46569 | M4: =EDATE(Assumptions!$B$6,11) -> 46600
A6: Historical Feb 23 comparison — 10 new paid users begin immediately
A7: Active paid users | B7: =MIN(B$3,Assumptions!$C$39)*Assumptions!$C$38 -> 10 | C7: =MIN(C$3,Assumptions!$C$39)*Assumptions!$C$38 -> 20 | D7: =MIN(D$3,Assumptions!$C$39)*Assumptions!$C$38 -> 30 | E7: =MIN(E$3,Assumptions!$C$39)*Assumptions!$C$38 -> 40 | F7: =MIN(F$3,Assumptions!$C$39)*Assumptions!$C$38 -> 50 | G7: =MIN(G$3,Assumptions!$C$39)*Assumptions!$C$38 -> 60 | H7: =MIN(H$3,Assumptions!$C$39)*Assumptions!$C$38 -> 60 | I7: =MIN(I$3,Assumptions!$C$39)*Assumptions!$C$38 -> 60 | ... M7: =MIN(M$3,Assumptions!$C$39)*Assumptions!$C$38 -> 60
A8: Revenue | B8: =B7*Assumptions!$C$36 -> 149.9 | C8: =C7*Assumptions!$C$36 -> 299.8 | D8: =D7*Assumptions!$C$36 -> 449.7 | E8: =E7*Assumptions!$C$36 -> 599.6 | F8: =F7*Assumptions!$C$36 -> 749.5 | G8: =G7*Assumptions!$C$36 -> 899.4 | H8: =H7*Assumptions!$C$36 -> 899.4 | I8: =I7*Assumptions!$C$36 -> 899.4 | ... M8: =M7*Assumptions!$C$36 -> 899.4
A9: Contribution | B9: =B7*Assumptions!$C$41 -> 94.8 | C9: =C7*Assumptions!$C$41 -> 189.6 | D9: =D7*Assumptions!$C$41 -> 284.4 | E9: =E7*Assumptions!$C$41 -> 379.2 | F9: =F7*Assumptions!$C$41 -> 474 | G9: =G7*Assumptions!$C$41 -> 568.8 | H9: =H7*Assumptions!$C$41 -> 568.8 | I9: =I7*Assumptions!$C$41 -> 568.8 | ... M9: =M7*Assumptions!$C$41 -> 568.8
A10: Fixed software OpEx | B10: =Assumptions!$C$40 -> 94 | C10: =Assumptions!$C$40 -> 94 | D10: =Assumptions!$C$40 -> 94 | E10: =Assumptions!$C$40 -> 94 | F10: =Assumptions!$C$40 -> 94 | G10: =Assumptions!$C$40 -> 94 | H10: =Assumptions!$C$40 -> 94 | I10: =Assumptions!$C$40 -> 94 | ... M10: =Assumptions!$C$40 -> 94
A11: Operating profit | B11: =B9-B10 -> 0.8 | C11: =C9-C10 -> 95.6 | D11: =D9-D10 -> 190.4 | E11: =E9-E10 -> 285.2 | F11: =F9-F10 -> 380 | G11: =G9-G10 -> 474.8 | H11: =H9-H10 -> 474.8 | I11: =I9-I10 -> 474.8 | ... M11: =M9-M10 -> 474.8
A12: Cumulative cash | B12: =SUM($B$11:B11) -> 0.8 | C12: =SUM($B$11:C11) -> 96.4 | D12: =SUM($B$11:D11) -> 286.8 | E12: =SUM($B$11:E11) -> 572 | F12: =SUM($B$11:F11) -> 952 | G12: =SUM($B$11:G11) -> 1426.8 | H12: =SUM($B$11:H11) -> 1901.6 | I12: =SUM($B$11:I11) -> 2376.4 | ... M12: =SUM($B$11:M11) -> 4275.6
A15: Current organic base case — one-month trial delay
A16: New trial users | B16: =Assumptions!$B$9 -> 500 | C16: =Assumptions!$B$9 -> 500 | D16: =Assumptions!$B$9 -> 500 | E16: =Assumptions!$B$9 -> 500 | F16: =Assumptions!$B$9 -> 500 | G16: =Assumptions!$B$9 -> 500 | H16: =Assumptions!$B$9 -> 500 | I16: =Assumptions!$B$9 -> 500 | ... M16: =Assumptions!$B$9 -> 500
A17: New paid starts | B17: =IF(B$3<=Assumptions!$B$12,0,Assumptions!$B$10) -> 0 | C17: =IF(C$3<=Assumptions!$B$12,0,Assumptions!$B$10) -> 10 | D17: =IF(D$3<=Assumptions!$B$12,0,Assumptions!$B$10) -> 10 | E17: =IF(E$3<=Assumptions!$B$12,0,Assumptions!$B$10) -> 10 | F17: =IF(F$3<=Assumptions!$B$12,0,Assumptions!$B$10) -> 10 | G17: =IF(G$3<=Assumptions!$B$12,0,Assumptions!$B$10) -> 10 | H17: =IF(H$3<=Assumptions!$B$12,0,Assumptions!$B$10) -> 10 | I17: =IF(I$3<=Assumptions!$B$12,0,Assumptions!$B$10) -> 10 | ... M17: =IF(M$3<=Assumptions!$B$12,0,Assumptions!$B$10) -> 10
A18: Active paid users | B18: =MIN(MAX(B$3-Assumptions!$B$12,0),Assumptions!$B$11)*Assumptions!$B$10 -> 0 | C18: =MIN(MAX(C$3-Assumptions!$B$12,0),Assumptions!$B$11)*Assumptions!$B$10 -> 10 | D18: =MIN(MAX(D$3-Assumptions!$B$12,0),Assumptions!$B$11)*Assumptions!$B$10 -> 20 | E18: =MIN(MAX(E$3-Assumptions!$B$12,0),Assumptions!$B$11)*Assumptions!$B$10 -> 30 | F18: =MIN(MAX(F$3-Assumptions!$B$12,0),Assumptions!$B$11)*Assumptions!$B$10 -> 40 | G18: =MIN(MAX(G$3-Assumptions!$B$12,0),Assumptions!$B$11)*Assumptions!$B$10 -> 50 | H18: =MIN(MAX(H$3-Assumptions!$B$12,0),Assumptions!$B$11)*Assumptions!$B$10 -> 60 | I18: =MIN(MAX(I$3-Assumptions!$B$12,0),Assumptions!$B$11)*Assumptions!$B$10 -> 60 | ... M18: =MIN(MAX(M$3-Assumptions!$B$12,0),Assumptions!$B$11)*Assumptions!$B$10 -> 60
A19: Revenue | B19: =B18*Assumptions!$B$13 -> 0 | C19: =C18*Assumptions!$B$13 -> 100 | D19: =D18*Assumptions!$B$13 -> 200 | E19: =E18*Assumptions!$B$13 -> 300 | F19: =F18*Assumptions!$B$13 -> 400 | G19: =G18*Assumptions!$B$13 -> 500 | H19: =H18*Assumptions!$B$13 -> 600 | I19: =I18*Assumptions!$B$13 -> 600 | ... M19: =M18*Assumptions!$B$13 -> 600
A20: Stripe cost | B20: =B18*(Assumptions!$B$13*Assumptions!$B$17+Assumptions!$B$18+Assumptions!$B$13*Assumptions!$B$19) -> 0 | C20: =C18*(Assumptions!$B$13*Assumptions!$B$17+Assumptions!$B$18+Assumptions!$B$13*Assumptions!$B$19) -> 6.6 | D20: =D18*(Assumptions!$B$13*Assumptions!$B$17+Assumptions!$B$18+Assumptions!$B$13*Assumptions!$B$19) -> 13.2 | E20: =E18*(Assumptions!$B$13*Assumptions!$B$17+Assumptions!$B$18+Assumptions!$B$13*Assumptions!$B$19) -> 19.8 | F20: =F18*(Assumptions!$B$13*Assumptions!$B$17+Assumptions!$B$18+Assumptions!$B$13*Assumptions!$B$19) -> 26.4 | G20: =G18*(Assumptions!$B$13*Assumptions!$B$17+Assumptions!$B$18+Assumptions!$B$13*Assumptions!$B$19) -> 33 | H20: =H18*(Assumptions!$B$13*Assumptions!$B$17+Assumptions!$B$18+Assumptions!$B$13*Assumptions!$B$19) -> 39.6 | I20: =I18*(Assumptions!$B$13*Assumptions!$B$17+Assumptions!$B$18+Assumptions!$B$13*Assumptions!$B$19) -> 39.6 | ... M20: =M18*(Assumptions!$B$13*Assumptions!$B$17+Assumptions!$B$18+Assumptions!$B$13*Assumptions!$B$19) -> 39.6
A21: Gemini cost (paid + trials) | B21: =(B18+B16)*Assumptions!$B$14*(Assumptions!$B$15/1000000*IF(B$4<Assumptions!$B$24,Assumptions!$B$20,Assumptions!$B$22)+Assumptions!$B$16/1000000*IF(B$4<Assumptions!$B$24,Assumptions!$B$21,Assumptions!$B$23)) -> 13.125 | C21: =(C18+C16)*Assumptions!$B$14*(Assumptions!$B$15/1000000*IF(C$4<Assumptions!$B$24,Assumptions!$B$20,Assumptions!$B$22)+Assumptions!$B$16/1000000*IF(C$4<Assumptions!$B$24,Assumptions!$B$21,Assumptions!$B$23)) -> 13.3875 | D21: =(D18+D16)*Assumptions!$B$14*(Assumptions!$B$15/1000000*IF(D$4<Assumptions!$B$24,Assumptions!$B$20,Assumptions!$B$22)+Assumptions!$B$16/1000000*IF(D$4<Assumptions!$B$24,Assumptions!$B$21,Assumptions!$B$23)) -> 13.65 | E21: =(E18+E16)*Assumptions!$B$14*(Assumptions!$B$15/1000000*IF(E$4<Assumptions!$B$24,Assumptions!$B$20,Assumptions!$B$22)+Assumptions!$B$16/1000000*IF(E$4<Assumptions!$B$24,Assumptions!$B$21,Assumptions!$B$23)) -> 13.9125 | F21: =(F18+F16)*Assumptions!$B$14*(Assumptions!$B$15/1000000*IF(F$4<Assumptions!$B$24,Assumptions!$B$20,Assumptions!$B$22)+Assumptions!$B$16/1000000*IF(F$4<Assumptions!$B$24,Assumptions!$B$21,Assumptions!$B$23)) -> 28.35 | G21: =(G18+G16)*Assumptions!$B$14*(Assumptions!$B$15/1000000*IF(G$4<Assumptions!$B$24,Assumptions!$B$20,Assumptions!$B$22)+Assumptions!$B$16/1000000*IF(G$4<Assumptions!$B$24,Assumptions!$B$21,Assumptions!$B$23)) -> 28.875 | H21: =(H18+H16)*Assumptions!$B$14*(Assumptions!$B$15/1000000*IF(H$4<Assumptions!$B$24,Assumptions!$B$20,Assumptions!$B$22)+Assumptions!$B$16/1000000*IF(H$4<Assumptions!$B$24,Assumptions!$B$21,Assumptions!$B$23)) -> 29.4 | I21: =(I18+I16)*Assumptions!$B$14*(Assumptions!$B$15/1000000*IF(I$4<Assumptions!$B$24,Assumptions!$B$20,Assumptions!$B$22)+Assumptions!$B$16/1000000*IF(I$4<Assumptions!$B$24,Assumptions!$B$21,Assumptions!$B$23)) -> 29.4 | ... M21: =(M18+M16)*Assumptions!$B$14*(Assumptions!$B$15/1000000*IF(M$4<Assumptions!$B$24,Assumptions!$B$20,Assumptions!$B$22)+Assumptions!$B$16/1000000*IF(M$4<Assumptions!$B$24,Assumptions!$B$21,Assumptions!$B$23)) -> 29.4
A22: Variable cost | B22: =SUM(B20:B21) -> 13.125 | C22: =SUM(C20:C21) -> 19.9875 | D22: =SUM(D20:D21) -> 26.85 | E22: =SUM(E20:E21) -> 33.7125 | F22: =SUM(F20:F21) -> 54.75 | G22: =SUM(G20:G21) -> 61.875 | H22: =SUM(H20:H21) -> 69 | I22: =SUM(I20:I21) -> 69 | ... M22: =SUM(M20:M21) -> 69
A23: Contribution | B23: =B19-B22 -> -13.125 | C23: =C19-C22 -> 80.0125 | D23: =D19-D22 -> 173.15 | E23: =E19-E22 -> 266.2875 | F23: =F19-F22 -> 345.25 | G23: =G19-G22 -> 438.125 | H23: =H19-H22 -> 531 | I23: =I19-I22 -> 531 | ... M23: =M19-M22 -> 531
A24: Fixed software OpEx | B24: =Assumptions!$B$28 -> 45 | C24: =Assumptions!$B$28 -> 45 | D24: =Assumptions!$B$28 -> 45 | E24: =Assumptions!$B$28 -> 45 | F24: =Assumptions!$B$28 -> 45 | G24: =Assumptions!$B$28 -> 45 | H24: =Assumptions!$B$28 -> 45 | I24: =Assumptions!$B$28 -> 45 | ... M24: =Assumptions!$B$28 -> 45
A25: Acquisition spend | B25: 0 | C25: 0 | D25: 0 | E25: 0 | F25: 0 | G25: 0 | H25: 0 | I25: 0 | J25: 0 | K25: 0 | L25: 0 | M25: 0
A26: Operating profit | B26: =B23-B24-B25 -> -58.125 | C26: =C23-C24-C25 -> 35.0125 | D26: =D23-D24-D25 -> 128.15 | E26: =E23-E24-E25 -> 221.2875 | F26: =F23-F24-F25 -> 300.25 | G26: =G23-G24-G25 -> 393.125 | H26: =H23-H24-H25 -> 486 | I26: =I23-I24-I25 -> 486 | ... M26: =M23-M24-M25 -> 486
A27: Cumulative cash | B27: =Assumptions!$B$31+SUM($B$26:B26) -> -58.125 | C27: =Assumptions!$B$31+SUM($B$26:C26) -> -23.1125 | D27: =Assumptions!$B$31+SUM($B$26:D26) -> 105.0375 | E27: =Assumptions!$B$31+SUM($B$26:E26) -> 326.325 | F27: =Assumptions!$B$31+SUM($B$26:F26) -> 626.575 | G27: =Assumptions!$B$31+SUM($B$26:G26) -> 1019.7 | H27: =Assumptions!$B$31+SUM($B$26:H26) -> 1505.7 | I27: =Assumptions!$B$31+SUM($B$26:I26) -> 1991.7 | ... M27: =Assumptions!$B$31+SUM($B$26:M26) -> 3935.7
A28: Monthly profitable? | B28: =IF(B26>0,"Yes","No") -> No | C28: =IF(C26>0,"Yes","No") -> Yes | D28: =IF(D26>0,"Yes","No") -> Yes | E28: =IF(E26>0,"Yes","No") -> Yes | F28: =IF(F26>0,"Yes","No") -> Yes | G28: =IF(G26>0,"Yes","No") -> Yes | H28: =IF(H26>0,"Yes","No") -> Yes | I28: =IF(I26>0,"Yes","No") -> Yes | ... M28: =IF(M26>0,"Yes","No") -> Yes
A29: Cumulative cash non-negative? | B29: =IF(B27>=0,"Yes","No") -> No | C29: =IF(C27>=0,"Yes","No") -> No | D29: =IF(D27>=0,"Yes","No") -> Yes | E29: =IF(E27>=0,"Yes","No") -> Yes | F29: =IF(F27>=0,"Yes","No") -> Yes | G29: =IF(G27>=0,"Yes","No") -> Yes | H29: =IF(H27>=0,"Yes","No") -> Yes | I29: =IF(I27>=0,"Yes","No") -> Yes | ... M29: =IF(M27>=0,"Yes","No") -> Yes
A32: Current paid-acquisition scenario — spend at 3:1 CAC ceiling
A33: New trial users | B33: =B16 -> 500 | C33: =C16 -> 500 | D33: =D16 -> 500 | E33: =E16 -> 500 | F33: =F16 -> 500 | G33: =G16 -> 500 | H33: =H16 -> 500 | I33: =I16 -> 500 | ... M33: =M16 -> 500
A34: New paid starts | B34: =B17 -> 0 | C34: =C17 -> 10 | D34: =D17 -> 10 | E34: =E17 -> 10 | F34: =F17 -> 10 | G34: =G17 -> 10 | H34: =H17 -> 10 | I34: =I17 -> 10 | ... M34: =M17 -> 10
A35: Active paid users | B35: =B18 -> 0 | C35: =C18 -> 10 | D35: =D18 -> 20 | E35: =E18 -> 30 | F35: =F18 -> 40 | G35: =G18 -> 50 | H35: =H18 -> 60 | I35: =I18 -> 60 | ... M35: =M18 -> 60
A36: Revenue | B36: =B19 -> 0 | C36: =C19 -> 100 | D36: =D19 -> 200 | E36: =E19 -> 300 | F36: =F19 -> 400 | G36: =G19 -> 500 | H36: =H19 -> 600 | I36: =I19 -> 600 | ... M36: =M19 -> 600
A37: Variable cost | B37: =B22 -> 13.125 | C37: =C22 -> 19.9875 | D37: =D22 -> 26.85 | E37: =E22 -> 33.7125 | F37: =F22 -> 54.75 | G37: =G22 -> 61.875 | H37: =H22 -> 69 | I37: =I22 -> 69 | ... M37: =M22 -> 69
A38: Contribution | B38: =B23 -> -13.125 | C38: =C23 -> 80.0125 | D38: =D23 -> 173.15 | E38: =E23 -> 266.2875 | F38: =F23 -> 345.25 | G38: =G23 -> 438.125 | H38: =H23 -> 531 | I38: =I23 -> 531 | ... M38: =M23 -> 531
A39: Fixed software OpEx | B39: =B24 -> 45 | C39: =C24 -> 45 | D39: =D24 -> 45 | E39: =E24 -> 45 | F39: =F24 -> 45 | G39: =G24 -> 45 | H39: =H24 -> 45 | I39: =I24 -> 45 | ... M39: =M24 -> 45
A40: Acquisition spend | B40: =Assumptions!$B$30*Assumptions!$B$10 -> 185.75 | C40: =Assumptions!$B$30*Assumptions!$B$10 -> 185.75 | D40: =Assumptions!$B$30*Assumptions!$B$10 -> 185.75 | E40: =Assumptions!$B$30*Assumptions!$B$10 -> 185.75 | F40: =Assumptions!$B$30*Assumptions!$B$10 -> 185.75 | G40: =Assumptions!$B$30*Assumptions!$B$10 -> 185.75 | H40: =Assumptions!$B$30*Assumptions!$B$10 -> 185.75 | I40: =Assumptions!$B$30*Assumptions!$B$10 -> 185.75 | ... M40: =Assumptions!$B$30*Assumptions!$B$10 -> 185.75
A41: Operating profit | B41: =B38-B39-B40 -> -243.875 | C41: =C38-C39-C40 -> -150.7375 | D41: =D38-D39-D40 -> -57.6 | E41: =E38-E39-E40 -> 35.5375 | F41: =F38-F39-F40 -> 114.5 | G41: =G38-G39-G40 -> 207.375 | H41: =H38-H39-H40 -> 300.25 | I41: =I38-I39-I40 -> 300.25 | ... M41: =M38-M39-M40 -> 300.25
A42: Cumulative cash | B42: =Assumptions!$B$31+SUM($B$41:B41) -> -243.875 | C42: =Assumptions!$B$31+SUM($B$41:C41) -> -394.6125 | D42: =Assumptions!$B$31+SUM($B$41:D41) -> -452.2125 | E42: =Assumptions!$B$31+SUM($B$41:E41) -> -416.675 | F42: =Assumptions!$B$31+SUM($B$41:F41) -> -302.175 | G42: =Assumptions!$B$31+SUM($B$41:G41) -> -94.8 | H42: =Assumptions!$B$31+SUM($B$41:H41) -> 205.45 | I42: =Assumptions!$B$31+SUM($B$41:I41) -> 505.7 | ... M42: =Assumptions!$B$31+SUM($B$41:M41) -> 1706.7
A43: Monthly profitable? | B43: =IF(B41>0,"Yes","No") -> No | C43: =IF(C41>0,"Yes","No") -> No | D43: =IF(D41>0,"Yes","No") -> No | E43: =IF(E41>0,"Yes","No") -> Yes | F43: =IF(F41>0,"Yes","No") -> Yes | G43: =IF(G41>0,"Yes","No") -> Yes | H43: =IF(H41>0,"Yes","No") -> Yes | I43: =IF(I41>0,"Yes","No") -> Yes | ... M43: =IF(M41>0,"Yes","No") -> Yes
A44: Cumulative cash non-negative? | B44: =IF(B42>=0,"Yes","No") -> No | C44: =IF(C42>=0,"Yes","No") -> No | D44: =IF(D42>=0,"Yes","No") -> No | E44: =IF(E42>=0,"Yes","No") -> No | F44: =IF(F42>=0,"Yes","No") -> No | G44: =IF(G42>=0,"Yes","No") -> No | H44: =IF(H42>=0,"Yes","No") -> Yes | I44: =IF(I42>=0,"Yes","No") -> Yes | ... M44: =IF(M42>=0,"Yes","No") -> Yes
A48: Period | B48: Historical Feb 23 | C48: Current organic | D48: Current paid CAC
...

Sheet Unit Economics
A1: Unit economics, CAC and LTV
A2: All values are contribution economics, not GAAP profit. The base case uses the higher published 2027 Gemini 3.8 Flash price so the CAC target is conservative. $7 and $5 are on Price Sensitivity.
A4: Metric | B4: Current value | C4: Plain-English meaning
A5: Monthly subscription price | B5: =Assumptions!B13 -> 10 | C5: What one paid user pays each month
A6: Stripe Payments fee | B6: =Assumptions!B13*Assumptions!B17+Assumptions!B18 -> 0.59 | C6: Card-processing cost on one $10 charge
A7: Stripe Billing fee | B7: =Assumptions!B13*Assumptions!B19 -> 0.07 | C7: Subscription-billing cost on one $10 charge
A8: Stripe total | B8: =SUM(B6:B7) -> 0.66 | C8: Payments plus Billing
A9: Gemini cost / user — 2026 | B9: =Assumptions!B14*(Assumptions!B15/1000000*Assumptions!B20+Assumptions!B16/1000000*Assumptions!B21) -> 0.02625 | C9: Modeled coaching calls at 2026 rate
A10: Gemini cost / user — 2027 | B10: =Assumptions!B14*(Assumptions!B15/1000000*Assumptions!B22+Assumptions!B16/1000000*Assumptions!B23) -> 0.0525 | C10: Modeled coaching calls at published 2027 rate
A11: Contribution / paid user | B11: =Assumptions!B13-B8-B10 -> 9.2875 | C11: Revenue left after variable costs
A12: Contribution margin | B12: =B11/Assumptions!B13 -> 0.92875 | C12: Contribution divided by price
A13: Break-even paid users — lean | B13: =CEILING(Assumptions!B25/B11,1) -> 5 | C13: Active paid users needed to cover $45 fixed stack
A14: Break-even paid users — monitored | B14: =CEILING(Assumptions!B26/B11,1) -> 8 | C14: Active paid users needed to cover $71 fixed stack
A15: Six-month contribution LTV | B15: =B11*Assumptions!B11 -> 55.725 | C15: Contribution earned over assumed paid lifetime
A16: 3:1 CAC ceiling | B16: =B15/3 -> 18.575 | C16: Maximum acquisition cost at a 3× LTV-to-CAC target
A17: CAC payback | B17: =B16/B11 -> 2 | C17: Months of contribution needed to repay CAC
A20: Lifetime and CAC sensitivity
A21: Paid lifetime (months) | B21: Contribution LTV | C21: 3:1 CAC ceiling | D21: Interpretation
A22: 3 | B22: =$A22*$B$11 -> 27.8625 | C22: =B22/3 -> 9.2875 | D22: Sensitivity only
A23: 6 | B23: =$A23*$B$11 -> 55.725 | C23: =B23/3 -> 18.575 | D23: Base assumption
A24: 12 | B24: =$A24*$B$11 -> 111.45 | C24: =B24/3 -> 37.15 | D24: Sensitivity only
A25: 18 | B25: =$A25*$B$11 -> 167.175 | C25: =B25/3 -> 55.725 | D25: Sensitivity only
A28: Short definitions
A29: CAC | B29: Cost to win one paying customer.
A30: LTV | B30: Contribution earned over a customer's paid lifetime.
A31: Contribution | B31: Revenue left after variable costs such as Stripe and Gemini.
A32: Fixed OpEx | B32: Monthly software cost that does not change with each customer.
A33: Break-even | B33: The point where monthly contribution covers fixed OpEx.
A34: Conversion | B34: The share of new trial users who become paid.
A35: MAU | B35: Monthly active users.

Sheet Price Sensitivity
A1: Price sensitivity — $10 versus $7 and $5
A2: Same unvalidated ramp and usage as Assumptions (500 trials/month, 2% conversion, 6-month lifetime, 10 coaching calls/user/month). Only price changes; conversion and lifetime are held constant, which is itself an untested assumption. Yellow = editable input; blue = formula; green = key output. Gemini at the published 2027 price unless a row says otherwise.
A5: Unit economics per paid user
A6: Metric | B6: Current | C6: Alternative | D6: Alternative | E6: Units
A7: Monthly price | B7: =Assumptions!B13 -> 10 | C7: 7 | D7: 5 | E7: USD / month
A8: Stripe Payments + Billing | B8: =B7*(Assumptions!$B$17+Assumptions!$B$19)+Assumptions!$B$18 -> 0.66 | C8: =C7*(Assumptions!$B$17+Assumptions!$B$19)+Assumptions!$B$18 -> 0.552 | D8: =D7*(Assumptions!$B$17+Assumptions!$B$19)+Assumptions!$B$18 -> 0.48 | E8: USD / charge
A9: Stripe share of price | B9: =IF(B7=0,0,B8/B7) -> 0.066 | C9: =IF(C7=0,0,C8/C7) -> 0.078857143 | D9: =IF(D7=0,0,D8/D7) -> 0.096 | E9: % of price
A10: Gemini cost / user — 2027 | B10: ='Unit Economics'!$B$10 -> 0.0525 | C10: ='Unit Economics'!$B$10 -> 0.0525 | D10: ='Unit Economics'!$B$10 -> 0.0525 | E10: 10 calls; no thinking tokens
A11: Contribution / paid user | B11: =B7-B8-B10 -> 9.2875 | C11: =C7-C8-C10 -> 6.3955 | D11: =D7-D8-D10 -> 4.4675 | E11: USD / month
A12: Contribution margin | B12: =IF(B7=0,0,B11/B7) -> 0.92875 | C12: =IF(C7=0,0,C11/C7) -> 0.91364286 | D12: =IF(D7=0,0,D11/D7) -> 0.8935 | E12: % of price
A13: Six-month contribution LTV | B13: =B11*Assumptions!$B$11 -> 55.725 | C13: =C11*Assumptions!$B$11 -> 38.373 | D13: =D11*Assumptions!$B$11 -> 26.805 | E13: USD
A14: 3:1 CAC ceiling | B14: =B13/3 -> 18.575 | C14: =C13/3 -> 12.791 | D14: =D13/3 -> 8.935 | E14: USD / new paid user
A16: Break-even active paid users (rounded up)
A17: Fixed cost covered | B17: Current | C17: Alternative | D17: Alternative | E17: Fixed USD / month
A18: Trial coaching cost / month (all trials, 2027) | B18: =Assumptions!$B$9*'Unit Economics'!$B$10 -> 26.25 | C18: =Assumptions!$B$9*'Unit Economics'!$B$10 -> 26.25 | D18: =Assumptions!$B$9*'Unit Economics'!$B$10 -> 26.25 | E18: Trials cost coaching but pay nothing
A19: Lean stack only (Unit Economics definition) | B19: =IF(B11<=0,"never",CEILING(Assumptions!$B$25/B11,1)) -> 5 | C19: =IF(C11<=0,"never",CEILING(Assumptions!$B$25/C11,1)) -> 8 | D19: =IF(D11<=0,"never",CEILING(Assumptions!$B$25/D11,1)) -> 11 | E19: =Assumptions!$B$25 -> 45
A20: Lean stack + trial coaching | B20: =IF(B11<=0,"never",CEILING((Assumptions!$B$25+B18)/B11,1)) -> 8 | C20: =IF(C11<=0,"never",CEILING((Assumptions!$B$25+C18)/C11,1)) -> 12 | D20: =IF(D11<=0,"never",CEILING((Assumptions!$B$25+D18)/D11,1)) -> 16 | E20: =(Assumptions!$B$25+B18) -> 71.25
A21: Monitored stack + trial coaching | B21: =IF(B11<=0,"never",CEILING((Assumptions!$B$26+B18)/B11,1)) -> 11 | C21: =IF(C11<=0,"never",CEILING((Assumptions!$B$26+C18)/C11,1)) -> 16 | D21: =IF(D11<=0,"never",CEILING((Assumptions!$B$26+D18)/D11,1)) -> 22 | E21: =(Assumptions!$B$26+B18) -> 97.25
A23: Steady state and what a lower price must earn back
A24: Metric | B24: Current | C24: Alternative | D24: Alternative | E24: Units
A25: Steady-state active paid users | B25: =Assumptions!$B$10*Assumptions!$B$11 -> 60 | C25: =Assumptions!$B$10*Assumptions!$B$11 -> 60 | D25: =Assumptions!$B$10*Assumptions!$B$11 -> 60 | E25: users
A26: Steady-state monthly profit (selected stack) | B26: =B25*B11-Assumptions!$B$28-B18 -> 486 | C26: =C25*C11-Assumptions!$B$28-C18 -> 312.48 | D26: =D25*D11-Assumptions!$B$28-D18 -> 196.8 | E26: USD / month
A27: Paid users needed to match current-price profit | B27: =IF(B11<=0,"n/a",($B$26+Assumptions!$B$28+B18)/B11) -> 60 | C27: =IF(C11<=0,"n/a",($B$26+Assumptions!$B$28+C18)/C11) -> 87.131577 | D27: =IF(D11<=0,"n/a",($B$26+Assumptions!$B$28+D18)/D11) -> 124.73419 | E27: users
A28: Trial-to-paid conversion needed for that | B28: =IF(B11<=0,"n/a",B27/(Assumptions!$B$11*Assumptions!$B$9)) -> 0.02 | C28: =IF(C11<=0,"n/a",C27/(Assumptions!$B$11*Assumptions!$B$9)) -> 0.029043859 | D28: =IF(D11<=0,"n/a",D27/(Assumptions!$B$11*Assumptions!$B$9)) -> 0.041578064 | E28: vs 2.00% assumed
A29: Paid-user multiple versus assumption | B29: =IF(B11<=0,"n/a",B27/B25) -> 1 | C29: =IF(C11<=0,"n/a",C27/C25) -> 1.4521929 | D29: =IF(D11<=0,"n/a",D27/D25) -> 2.0789032 | E29: x
A31: Profitability timing (month numbers from Forecast 12M)
A32: Scenario | B32: Current | C32: Alternative | D32: Alternative | E32: Basis
A33: Price | B33: =B7 -> 10 | C33: =C7 -> 7 | D33: =D7 -> 5
A34: Organic: first profitable month | B34: =IF(SUM(B65:M65)=0,"none in 12",MATCH(1,B65:M65,0)) -> 2 | C34: =IF(SUM(B75:M75)=0,"none in 12",MATCH(1,B75:M75,0)) -> 2 | D34: =IF(SUM(B85:M85)=0,"none in 12",MATCH(1,B85:M85,0)) -> 3 | E34: First month the flag row turns 1
A35: Organic: cumulative cash ≥ $0 from month | B35: =IF(SUM(B66:M66)=0,"none in 12",MATCH(1,B66:M66,0)) -> 3 | C35: =IF(SUM(B76:M76)=0,"none in 12",MATCH(1,B76:M76,0)) -> 3 | D35: =IF(SUM(B86:M86)=0,"none in 12",MATCH(1,B86:M86,0)) -> 4
A36: Paid CAC at own 3:1 ceiling: first profitable month | B36: =IF(SUM(B67:M67)=0,"none in 12",MATCH(1,B67:M67,0)) -> 4 | C36: =IF(SUM(B77:M77)=0,"none in 12",MATCH(1,B77:M77,0)) -> 4 | D36: =IF(SUM(B87:M87)=0,"none in 12",MATCH(1,B87:M87,0)) -> 5 | E36: Paid scenario spends each price’s own CAC ceiling (row 14)
A37: Paid CAC at own 3:1 ceiling: cumulative cash ≥ $0 from month | B37: =IF(SUM(B68:M68)=0,"none in 12",MATCH(1,B68:M68,0)) -> 7 | C37: =IF(SUM(B78:M78)=0,"none in 12",MATCH(1,B78:M78,0)) -> 7 | D37: =IF(SUM(B88:M88)=0,"none in 12",MATCH(1,B88:M88,0)) -> 9
A39: Break-even price by active paid users
A40: Active paid users | B40: Lean only | C40: Lean + trials | D40: Monitored + trials | E40: Formula
A41: 10 | B41: =(Assumptions!$B$25/A41+Assumptions!$B$18+'Unit Economics'!$B$10)/(1-Assumptions!$B$17-Assumptions!$B$19) -> 5.0337137 | C41: =((Assumptions!$B$25+$B$18)/A41+Assumptions!$B$18+'Unit Economics'!$B$10)/(1-Assumptions!$B$17-Assumptions!$B$19) -> 7.7567427 | D41: =((Assumptions!$B$26+$B$18)/A41+Assumptions!$B$18+'Unit Economics'!$B$10)/(1-Assumptions!$B$17-Assumptions!$B$19) -> 10.453838 | E41: (fixed ÷ users + $0.30 + Gemini) ÷ (1 − 3.6%)
A42: 20 | B42: =(Assumptions!$B$25/A42+Assumptions!$B$18+'Unit Economics'!$B$10)/(1-Assumptions!$B$17-Assumptions!$B$19) -> 2.6996888 | C42: =((Assumptions!$B$25+$B$18)/A42+Assumptions!$B$18+'Unit Economics'!$B$10)/(1-Assumptions!$B$17-Assumptions!$B$19) -> 4.0612033 | D42: =((Assumptions!$B$26+$B$18)/A42+Assumptions!$B$18+'Unit Economics'!$B$10)/(1-Assumptions!$B$17-Assumptions!$B$19) -> 5.409751
A43: 30 | B43: =(Assumptions!$B$25/A43+Assumptions!$B$18+'Unit Economics'!$B$10)/(1-Assumptions!$B$17-Assumptions!$B$19) -> 1.9216805 | C43: =((Assumptions!$B$25+$B$18)/A43+Assumptions!$B$18+'Unit Economics'!$B$10)/(1-Assumptions!$B$17-Assumptions!$B$19) -> 2.8293568 | D43: =((Assumptions!$B$26+$B$18)/A43+Assumptions!$B$18+'Unit Economics'!$B$10)/(1-Assumptions!$B$17-Assumptions!$B$19) -> 3.7283887
A44: 60 | B44: =(Assumptions!$B$25/A44+Assumptions!$B$18+'Unit Economics'!$B$10)/(1-Assumptions!$B$17-Assumptions!$B$19) -> 1.1436722 | C44: =((Assumptions!$B$25+$B$18)/A44+Assumptions!$B$18+'Unit Economics'!$B$10)/(1-Assumptions!$B$17-Assumptions!$B$19) -> 1.5975104 | D44: =((Assumptions!$B$26+$B$18)/A44+Assumptions!$B$18+'Unit Economics'!$B$10)/(1-Assumptions!$B$17-Assumptions!$B$19) -> 2.0470263
A46: Heavy-user coaching exposure (2027 Gemini price)
A47: Metric | B47: Current | C47: Alternative | D47: Alternative | E47: Units
...

Sheet Checks
A1: Model checks and audit controls
A2: PASS means the model ties to its stated assumptions. It does not mean the commercial assumptions will occur.
A4: Check | B4: Actual | C4: Expected | D4: Difference | E4: Tolerance | F4: Status | G4: Where to fix / note
A5: New paid ramp equals trials × conversion | B5: =Assumptions!B10 -> 10 | C5: =Assumptions!B9*Assumptions!B8 -> 10 | D5: =B5-C5 -> 0 | E5: 0.0001 | F5: =IF(ABS(D5)<=E5,"OK","FAIL") -> OK | G5: Assumptions B8:B10
A6: Lean fixed stack ties | B6: =Assumptions!B25 -> 45 | C6: ='Stack Comparison'!C18 -> 45 | D6: =B6-C6 -> 0 | E6: 0.01 | F6: =IF(ABS(D6)<=E6,"OK","FAIL") -> OK | G6: Stack Comparison C7:C17
A7: Monitored fixed stack ties | B7: =Assumptions!B26 -> 71 | C7: ='Stack Comparison'!D18 -> 71 | D7: =B7-C7 -> 0 | E7: 0.01 | F7: =IF(ABS(D7)<=E7,"OK","FAIL") -> OK | G7: Stack Comparison D7:D17
A8: Unit contribution ties | B8: ='Unit Economics'!B11 -> 9.2875 | C8: =Assumptions!B13-'Unit Economics'!B8-'Unit Economics'!B10 -> 9.2875 | D8: =B8-C8 -> 0 | E8: 0.0001 | F8: =IF(ABS(D8)<=E8,"OK","FAIL") -> OK | G8: Unit Economics B5:B11
A9: LTV ties to lifetime | B9: ='Unit Economics'!B15 -> 55.725 | C9: ='Unit Economics'!B11*Assumptions!B11 -> 55.725 | D9: =B9-C9 -> 0 | E9: 0.01 | F9: =IF(ABS(D9)<=E9,"OK","FAIL") -> OK | G9: Unit Economics B15
A10: CAC ceiling is LTV / 3 | B10: ='Unit Economics'!B16 -> 18.575 | C10: ='Unit Economics'!B15/3 -> 18.575 | D10: =B10-C10 -> 0 | E10: 0.01 | F10: =IF(ABS(D10)<=E10,"OK","FAIL") -> OK | G10: Unit Economics B16
A11: Current steady-state paid users | B11: ='Forecast 12M'!H18 -> 60 | C11: =Assumptions!B10*Assumptions!B11 -> 60 | D11: =B11-C11 -> 0 | E11: 0 | F11: =IF(ABS(D11)<=E11,"OK","FAIL") -> OK | G11: Forecast 12M row 18
A12: Current Month 1 paid users reflect trial | B12: ='Forecast 12M'!B18 -> 0 | C12: 0 | D12: =B12-C12 -> 0 | E12: 0 | F12: =IF(ABS(D12)<=E12,"OK","FAIL") -> OK | G12: Forecast 12M B18
A13: Historical Month 1 profit reproduces revised model | B13: ='Forecast 12M'!B11 -> 0.8 | C13: 0.8 | D13: =B13-C13 -> 1.1324275e-14 | E13: 0.01 | F13: =IF(ABS(D13)<=E13,"OK","FAIL") -> OK | G13: 10 × $9.48 − $94
A14: Prior $85 LTV mismatch is surfaced | B14: 85 | C14: ='Prior Models'!C13 -> 56.88 | D14: =B14-C14 -> 28.12 | E14: 0.01 | F14: =IF(ABS(D14)>E14,"OK","FAIL") -> OK | G14: OK means the historical mismatch is visible
A15: Current comparison contribution ties | B15: =Assumptions!E41 -> 9.2875 | C15: ='Unit Economics'!B11 -> 9.2875 | D15: =B15-C15 -> 0 | E15: 0.0001 | F15: =IF(ABS(D15)<=E15,"OK","FAIL") -> OK | G15: Assumptions E41 / Unit Economics B11
A17: Overall model status
A18: =IF(COUNTIF(F5:F15,"FAIL")+COUNTIF(F20:F30,"FAIL")=0,"MODEL STATUS: PASS","MODEL STATUS: FAIL") -> MODEL STATUS: PASS | D18: Financial audit completed: historical claims reconciled; trial and paid coaching usage included; Gemini's 2027 price step included; fixed and variable costs separated; paid CAC shown separately; forecast horizon tied to the fixed 12-month layout. PASS confirms formula consistency, not commercial validation.
A20: Stack comparison 2026 variable cost | B20: ='Stack Comparison'!C26 -> 0.68625 | C20: ='Unit Economics'!B8+'Unit Economics'!B9 -> 0.68625 | D20: =B20-C20 -> 0 | E20: 0.0001 | F20: =IF(ABS(D20)<=E20,"OK","FAIL") -> OK | G20: Stack Comparison C24:C26 / Unit Economics
A21: Stack comparison 2027 variable cost | B21: ='Stack Comparison'!D26 -> 0.7125 | C21: ='Unit Economics'!B8+'Unit Economics'!B10 -> 0.7125 | D21: =B21-C21 -> 0 | E21: 0.0001 | F21: =IF(ABS(D21)<=E21,"OK","FAIL") -> OK | G21: Stack Comparison D24:D26 / Unit Economics
A22: Month 1 trial coaching cost included | B22: ='Forecast 12M'!B21 -> 13.125 | C22: =Assumptions!B9*'Unit Economics'!B9 -> 13.125 | D22: =B22-C22 -> 0 | E22: 0.0001 | F22: =IF(ABS(D22)<=E22,"OK","FAIL") -> OK | G22: Forecast 12M B21 / 500 active trials
A23: Forecast horizon matches forecast columns | B23: =Assumptions!B7 -> 12 | C23: =COLUMNS('Forecast 12M'!B3:M3) -> 12 | D23: =B23-C23 -> 0 | E23: 0 | F23: =IF(ABS(D23)<=E23,"OK","FAIL") -> OK | G23: Assumptions B7 / Forecast 12M B:M
A24: Forecast month index present | B24: =SUM('Forecast 12M'!B3:M3) -> 78 | C24: 78 | D24: =B24-C24 -> 0 | E24: 0 | F24: =IF(ABS(D24)<=E24,"OK","FAIL") -> OK | G24: Forecast 12M row 3 (unmerged 2026-10-12)
A25: Price Sensitivity current contribution ties | B25: ='Price Sensitivity'!B11 -> 9.2875 | C25: ='Unit Economics'!B11 -> 9.2875 | D25: =B25-C25 -> 0 | E25: 0.0001 | F25: =IF(ABS(D25)<=E25,"OK","FAIL") -> OK | G25: Price Sensitivity B11
A26: Price Sensitivity current lean break-even ties | B26: ='Price Sensitivity'!B19 -> 5 | C26: ='Unit Economics'!B13 -> 5 | D26: =B26-C26 -> 0 | E26: 0 | F26: =IF(ABS(D26)<=E26,"OK","FAIL") -> OK | G26: Price Sensitivity B19
A27: Price Sensitivity current organic profit row ties | B27: =SUMPRODUCT(ABS('Price Sensitivity'!B61:M61-'Forecast 12M'!B26:M26)) -> 0 | C27: 0 | D27: =B27-C27 -> 0 | E27: 0.0001 | F27: =IF(ABS(D27)<=E27,"OK","FAIL") -> OK | G27: Price Sensitivity row 61 vs Forecast row 26
A28: Price Sensitivity current paid-CAC profit row ties | B28: =SUMPRODUCT(ABS('Price Sensitivity'!B63:M63-'Forecast 12M'!B41:M41)) -> 0 | C28: 0 | D28: =B28-C28 -> 0 | E28: 0.0001 | F28: =IF(ABS(D28)<=E28,"OK","FAIL") -> OK | G28: Price Sensitivity row 63 vs Forecast row 41
A29: Price Sensitivity steady-state profit ties | B29: ='Price Sensitivity'!B26 -> 486 | C29: ='Forecast 12M'!M26 -> 486 | D29: =B29-C29 -> 0 | E29: 0.0001 | F29: =IF(ABS(D29)<=E29,"OK","FAIL") -> OK | G29: Price Sensitivity B26 vs Forecast M26
A30: Price Sensitivity paid-CAC cash month ties | B30: ='Price Sensitivity'!B37 -> 7 | C30: =MATCH("Yes",'Forecast 12M'!B44:M44,0) -> 7 | D30: =B30-C30 -> 0 | E30: 0 | F30: =IF(ABS(D30)<=E30,"OK","FAIL") -> OK | G30: Price Sensitivity B37 vs Summary C28

Sheet Sources
A1: Sources and audit trail
A2: Rows dated 2026-10-12 were re-checked against the official page or repository on that date; rows still dated 2026-09-05 were not re-checked. Historical assumptions come from archived planning documents and are preserved for comparison, not treated as current facts.
A4: Input / service | B4: Value used | C4: Units | D4: As of | E4: Source type | F4: Source | G4: Reference | H4: Notes
A5: Supabase Pro | B5: 25 | C5: USD/month | D5: 2026-10-12 | E5: Official pricing | F5: Supabase | G5: https://supabase.com/pricing | H5: Pro from $25/mo; $10 compute credit (one Micro); 100k MAU; 250 GB egress; 2M Edge invocations
A6: Vercel Pro | B6: 20 | C6: USD/month | D6: 2026-10-12 | E6: Official pricing | F6: Vercel | G6: https://vercel.com/docs/plans/pro | H6: $20 platform fee incl. 1 deploying seat and $20 usage credit; Flat Rate CDN 1M requests / 1 TB
A7: Stripe Payments | B7: 0.029 | C7: % + $0.30 | D7: 2026-10-12 | E7: Official pricing | F7: Stripe | G7: https://stripe.com/pricing | H7: Domestic cards; +1.5% international, +1% currency conversion
A8: Stripe Billing | B8: 0.007 | C8: % of volume | D8: 2026-10-12 | E8: Official pricing | F8: Stripe | G8: https://stripe.com/billing/pricing | H8: Pay-as-you-go 0.7% of Billing volume; no recurring fee
A9: PostHog | B9: 0 | C9: base USD/month | D9: 2026-10-12 | E9: Official pricing | F9: PostHog | G9: https://posthog.com/pricing | H9: Free: 1M analytics events, 5K recordings, 1M flag requests, 100K exceptions; overages not modeled
A10: Sentry Developer | B10: 0 | C10: USD/month | D10: 2026-10-12 | E10: Official pricing | F10: Sentry | G10: https://sentry.io/pricing/ | H10: Lean base; 5k errors; one user
A11: Sentry Team | B11: 26 | C11: USD/month | D11: 2026-10-12 | E11: Official pricing | F11: Sentry | G11: https://sentry.io/pricing/ | H11: $312/yr annual billing; monthly-billing price not shown on page
A12: GitHub Free | B12: 0 | C12: USD/month | D12: 2026-10-12 | E12: GitHub API | F12: GitHub | G12: https://api.github.com/repos/relativityE/speaksharp | H12: Repository visibility verified public on 2026-10-12
A13: Historical Resend Pro | B13: 20 | C13: USD/month | D13: 2026-09-05 | E13: Official pricing | F13: Resend | G13: https://resend.com/pricing | H13: Historical only; current plan uses Gmail
A14: Current Gmail | B14: 0 | C14: incremental USD/month | D14: 2026-09-05 | E14: Management direction | F14: User decision | G14: https://mail.google.com/ | H14: Existing Gmail; Workspace Starter optional at $7/user/month annual
A15: Google Workspace Starter option | B15: 7 | C15: USD/user/month | D15: 2026-09-05 | E15: Official pricing | F15: Google | G15: https://workspace.google.com/pricing.html | H15: Not included in base
A16: AssemblyAI current comparator | B16: 0.15 | C16: USD/hour | D16: 2026-09-05 | E16: Official pricing | F16: AssemblyAI | G16: https://www.assemblyai.com/pricing | H16: Not used by current product; old model used $0.47/hour
... A19: Gemini 3.5 Flash-Lite | B19: 0.3 | C19: input USD/1M | D19: 2026-10-12 | E19: Official pricing | F19: Google AI | G19: https://ai.google.dev/gemini-api/docs/pricing | H19: Lower-cost benchmark candidate; $2.50 output
A20: Gemini deprecation mapping | C20: n/a | D20: 2026-09-05 | E20: Official documentation | F20: Google AI | G20: https://ai.google.dev/gemini-api/docs/deprecations | H20: Legacy 3 Flash Preview → 3.6 Flash
A21: Current price and trial | B21: 10 | C21: USD/month after 30 days | D21: 2026-10-12 | E21: Current product requirement | F21: SpeakSharp | G21: product_release/PRODUCT_REQUIREMENTS.md | H21: PRODUCT_REQUIREMENTS.md line 115 ($10/month after trial); billing not activated; revenue remains projection
A22: Current Gemini code model | C22: model id | D22: 2026-10-12 | E22: Code | F22: SpeakSharp | G22: backend/supabase/functions/get-ai-suggestions/contract.json | H22: gemini-3.8-flash
A23: Current private STT candidate | B23: 80.55 | C23: MB model bundle | D23: 2026-10-12 | E23: Code / local asset | F23: SpeakSharp | G23: frontend/src/config/private-stt.config.json | H23: v2:base.en; 80,553,222 bytes measured in frontend/public/models/whisper-base.en
A24: Prior pricing assumptions | C24: historical model | D24: 2026-02 | E24: Archived planning | F24: SpeakSharp | G24: product_release/archive/superseded-docs-2026-08-29/pricing_analysis.md | H24: $7.99 and $14.99 versions
A25: Prior CFO forecast | C25: historical model | D25: 2026-02 | E25: Archived planning | F25: SpeakSharp | G25: product_release/archive/legacy-docs/d31102a8/PRD.md | H25: Conversion, lifetime, CAC and ramp assumptions
A26: Gemini 3.6 Flash | B26: 0.75 | C26: input USD/1M through 2026 | D26: 2026-10-12 | E26: Official pricing | F26: Google AI | G26: https://ai.google.dev/gemini-api/docs/pricing | H26: Prior planning baseline; identical price schedule to 3.8 Flash
A27: Gemini 3.8 Flash thinking default | B27: medium | C27: thinking_level | D27: 2026-10-12 | E27: Official documentation | F27: Google AI | G27: https://ai.google.dev/gemini-api/docs/latest-model | H27: Code sets no thinking_level, so the default applies
A28: Coaching daily cap | B28: 10 | C28: uncached calls / user / UTC day | D28: 2026-10-12 | E28: Code | F28: SpeakSharp | G28: backend/supabase/functions/get-ai-suggestions/contract.json | H28: uncachedGenerationCapPerUtcDay
A29: Coaching token usage telemetry | B29: none | C29: n/a | D29: 2026-10-12 | E29: Code search | F29: SpeakSharp | G29: backend/, frontend/src, scripts, tests | H29: No usageMetadata / thoughtsTokenCount capture found; thinking cost unmeasured
